Workbook

Sheet Sheet1
A1: userid | B1: password | C1: pdf
A2: =[1]값목록!A1 -> 이상수 | B2: =[1]값목록!B1 -> 14816 | C2: =A2&".pdf" -> 이상수.pdf
A3: =[1]값목록!A2 -> 김민수 | B3: =[1]값목록!B2 -> 56296 | C3: =A3&".pdf" -> 김민수.pdf
A4: =[1]값목록!A3 -> 박종은 | B4: =[1]값목록!B3 -> 40798 | C4: =A4&".pdf" -> 박종은.pdf
A5: =[1]값목록!A4 -> 최우진 | B5: =[1]값목록!B4 -> 42510 | C5: =A5&".pdf" -> 최우진.pdf
A6: =[1]값목록!A5 -> 이복미 | B6: =[1]값목록!B5 -> 23631 | C6: =A6&".pdf" -> 이복미.pdf
A7: =[1]값목록!A6 -> 정희수 | B7: =[1]값목록!B6 -> 81271 | C7: =A7&".pdf" -> 정희수.pdf
A8: =[1]값목록!A7 -> 안정숙 | B8: =[1]값목록!B7 -> 08982 | C8: =A8&".pdf" -> 안정숙.pdf
A9: =[1]값목록!A8 -> 황경애 | B9: =[1]값목록!B8 -> 49126 | C9: =A9&".pdf" -> 황경애.pdf
A10: =[1]값목록!A9 -> 최지혜 | B10: =[1]값목록!B9 -> 50835 | C10: =A10&".pdf" -> 최지혜.pdf
A11: =[1]값목록!A10 -> 양유정 | B11: =[1]값목록!B10 -> 52172 | C11: =A11&".pdf" -> 양유정.pdf
A12: =[1]값목록!A11 -> 안가을 | B12: =[1]값목록!B11 -> 75095 | C12: =A12&".pdf" -> 안가을.pdf
A13: =[1]값목록!A12 -> 설정열 | B13: =[1]값목록!B12 -> 44893 | C13: =A13&".pdf" -> 설정열.pdf
... A21: =[1]값목록!A20 -> 윤상문 | B21: =[1]값목록!B20 -> 71319 | C21: =A21&".pdf" -> 윤상문.pdf
A22: 이상률 | B22: 32373 | C22: =A22&".pdf" -> 이상률.pdf
A23: 이영승 | B23: 82027 | C23: =A23&".pdf" -> 이영승.pdf
A24: 이영일 | B24: 56455 | C24: =A24&".pdf" -> 이영일.pdf
A25: 강재병 | B25: 28869 | C25: =A25&".pdf" -> 강재병.pdf
A26: 서원 | B26: 11065 | C26: =A26&".pdf" -> 서원.pdf
A27: 반재호 | B27: 65903 | C27: =A27&".pdf" -> 반재호.pdf
A28: 송순천 | B28: 46327 | C28: =A28&".pdf" -> 송순천.pdf
A29: 최재경 | B29: 33130 | C29: =A29&".pdf" -> 최재경.pdf
A30: 유재철 | B30: 27154 | C30: =A30&".pdf" -> 유재철.pdf
A31: 송영선 | B31: 74395 | C31: =A31&".pdf" -> 송영선.pdf
A32: 조상숙 | B32: 39673 | C32: =A32&".pdf" -> 조상숙.pdf
A33: 김상태 | B33: 43168 | C33: =A33&".pdf" -> 김상태.pdf
... A53: 정태흥 | B53: 29464 | C53: =A53&".pdf" -> 정태흥.pdf
A54: 최두나 | B54: 50436 | C54: =A54&".pdf" -> 최두나.pdf
A55: 이지훈 | B55: 80660 | C55: =A55&".pdf" -> 이지훈.pdf
A56: 최정홍 | B56: 47588 | C56: =A56&".pdf" -> 최정홍.pdf
A57: 이상곤 | B57: 37422 | C57: =A57&".pdf" -> 이상곤.pdf
A58: 안상오 | B58: 19448 | C58: =A58&".pdf" -> 안상오.pdf
A59: 류해원 | B59: 42348 | C59: =A59&".pdf" -> 류해원.pdf
A60: 김한섭 | B60: 84083 | C60: =A60&".pdf" -> 김한섭.pdf
A61: 박웅 | B61: 62768 | C61: =A61&".pdf" -> 박웅.pdf
A62: 권영신 | B62: 18711 | C62: =A62&".pdf" -> 권영신.pdf
A63: 박수민 | B63: 31875 | C63: =A63&".pdf" -> 박수민.pdf
A64: 김민혜 | B64: 61795 | C64: =A64&".pdf" -> 김민혜.pdf
A65: 김광수 | B65: 27267 | C65: =A65&".pdf" -> 김광수.pdf
A66: 김일환 | B66: 42544 | C66: =A66&".pdf" -> 김일환.pdf
...
